{"cveId": "CVE-2019-10904", "cwe": ["CWE-79", "CWE-79"], "cvss": [{"baseScore": "4.3", "version": "2.0", "Attack Vector": "None", "Attack Complexity": "M", "Privileges Required": "None", "User Interaction": "None", "Scope": "None", "Confidentiality Impact": "None", "Integrity Impact": "P", "Availability Impact": "None"}], "references": ["https://github.com/python/bugs.python.org/issues/34", "https://bugs.python.org/issue36391", "https://www.openwall.com/lists/oss-security/2019/04/05/1", "http://www.openwall.com/lists/oss-security/2019/04/07/1", "https://lists.debian.org/debian-lts-announce/2019/04/msg00009.html"], "description": ["Roundup 1.6 allows XSS via the URI because frontends/roundup.cgi and roundup/cgi/wsgi_handler.py mishandle 404 errors."], "published": "2019-04-06T20:29:00.230", "state": "PUBLIC", "vendorName": ["n/a"], "productName": ["n/a"], "github": {"advisories": [], "commits": [], "pocAdvisorie": null, "repo": null, "info": {}}, "pocList": []}