{"cveId": "CVE-2023-28858", "cwe": ["CWE-193", "CWE-193"], "cvss": [{"baseScore": "3.7", "version": "3.1", "Attack Vector": "None", "Attack Complexity": "High", "Privileges Required": "None", "User Interaction": "None", "Scope": "Unchaged", "Confidentiality Impact": "Low", "Integrity Impact": "None", "Availability Impact": "None"}], "references": ["https://github.com/redis/redis-py/pull/2641", "https://github.com/redis/redis-py/issues/2624", "https://github.com/redis/redis-py/compare/v4.5.2...v4.5.3", "https://github.com/redis/redis-py/compare/v4.4.2...v4.4.3", "https://github.com/redis/redis-py/compare/v4.3.5...v4.3.6", "https://openai.com/blog/march-20-chatgpt-outage"], "description": ["redis-py before 4.5.3 leaves a connection open after canceling an async Redis command at an inopportune time, and can send response data to the client of an unrelated request in an off-by-one manner. NOTE: this CVE Record was initially created in response to reports about ChatGPT, and 4.3.6, 4.4.3, and 4.5.3 were released (changing the behavior for pipeline operations); however, please see CVE-2023-28859 about addressing data leakage across AsyncIO connections in general."], "published": "2023-03-26T19:15:06.780", "state": "PUBLIC", "vendorName": ["n/a"], "productName": ["n/a"], "github": {"advisories": [], "commits": [], "pocAdvisorie": null, "repo": null, "info": {}}, "pocList": []}